<?xml version="1.0" ?>
<!-- Generated using onshape-to-robot -->
<!-- Onshape document_id: 0d8fb7f5563559787c5a3429 -->
<robot name="robot_arm">
  <!-- Link urdf_l_limb_stand_assembly -->
  <link name="urdf_l_limb_stand_assembly">
    <inertial>
      <origin xyz="0.15231 0.00126822 -0.0733771" rpy="0 0 0"/>
      <mass value="12.7824"/>
      <inertia ixx="0.319682" ixy="2.7236e-08" ixz="0.0107613" iyy="0.0695316" iyz="1.98209e-07" izz="0.343485"/>
    </inertial>
    <!-- Part table -->
    <visual>
      <origin xyz="0.171858 0.00126819 -0.0923205" rpy="-3.14159 2.84025e-16 -1.25251e-16"/>
      <geometry>
        <mesh filename="package://assets/table.stl"/>
      </geometry>
      <material name="table_material">
        <color rgba="0.615686 0.811765 0.929412 1"/>
      </material>
    </visual>
    <collision>
      <origin xyz="0.171858 0.00126819 -0.0923205" rpy="-3.14159 2.84025e-16 -1.25251e-16"/>
      <geometry>
        <mesh filename="package://assets/table.stl"/>
      </geometry>
    </collision>
    <!-- Part menghina_x6 -->
    <visual>
      <origin xyz="0.0868579 0.00126819 6.80296e-06" rpy="2.47509e-62 -1.21801e-78 1.5708"/>
      <geometry>
        <mesh filename="package://assets/menghina_x6.stl"/>
      </geometry>
      <material name="menghina_x6_material">
        <color rgba="0.32549 0.529412 0.752941 1"/>
      </material>
    </visual>
    <collision>
      <origin xyz="0.0868579 0.00126819 6.80296e-06" rpy="2.47509e-62 -1.21801e-78 1.5708"/>
      <geometry>
        <mesh filename="package://assets/menghina_x6.stl"/>
      </geometry>
    </collision>
    <!-- Part spacer_x6_menghina_m4x60 -->
    <visual>
      <origin xyz="0.00685786 0.00126819 6.80296e-06" rpy="1.5708 -1.5708 0"/>
      <geometry>
        <mesh filename="package://assets/spacer_x6_menghina_m4x60.stl"/>
      </geometry>
      <material name="spacer_x6_menghina_m4x60_material">
        <color rgba="0.596078 0.121569 0.67451 1"/>
      </material>
    </visual>
    <collision>
      <origin xyz="0.00685786 0.00126819 6.80296e-06" rpy="1.5708 -1.5708 0"/>
      <geometry>
        <mesh filename="package://assets/spacer_x6_menghina_m4x60.stl"/>
      </geometry>
    </collision>
    <!-- Part rotor_x6_p20_60 -->
    <visual>
      <origin xyz="0.141358 0.00126819 6.80296e-06" rpy="-1.25251e-16 -1.5708 0"/>
      <geometry>
        <mesh filename="package://assets/rotor_x6_p20_60.stl"/>
      </geometry>
      <material name="rotor_x6_p20_60_material">
        <color rgba="0.65098 0.486275 0.0196078 1"/>
      </material>
    </visual>
    <collision>
      <origin xyz="0.141358 0.00126819 6.80296e-06" rpy="-1.25251e-16 -1.5708 0"/>
      <geometry>
        <mesh filename="package://assets/rotor_x6_p20_60.stl"/>
      </geometry>
    </collision>
    <!-- Part stator_x6_p20_60 -->
    <visual>
      <origin xyz="0.141358 0.00126819 6.80296e-06" rpy="-1.25251e-16 -1.5708 0"/>
      <geometry>
        <mesh filename="package://assets/stator_x6_p20_60.stl"/>
      </geometry>
      <material name="stator_x6_p20_60_material">
        <color rgba="0.960784 0.835294 0.470588 1"/>
      </material>
    </visual>
    <collision>
      <origin xyz="0.141358 0.00126819 6.80296e-06" rpy="-1.25251e-16 -1.5708 0"/>
      <geometry>
        <mesh filename="package://assets/stator_x6_p20_60.stl"/>
      </geometry>
    </collision>
  </link>
  <!-- Link urdf_l_shoulder_assembly -->
  <link name="urdf_l_shoulder_assembly">
    <inertial>
      <origin xyz="-0.00509657 -9.94177e-07 -0.0751786" rpy="0 0 0"/>
      <mass value="2.97837"/>
      <inertia ixx="0.00348255" ixy="-3.74291e-08" ixz="2.44885e-05" iyy="0.00306396" iyz="-6.6893e-08" izz="0.00281696"/>
    </inertial>
    <!-- Part l_shoulder -->
    <visual>
      <origin xyz="-0.00130076 -6.96521e-06 -0.0582746" rpy="-1.5708 -1.5708 0"/>
      <geometry>
        <mesh filename="package://assets/l_shoulder.stl"/>
      </geometry>
      <material name="l_shoulder_material">
        <color rgba="0.615686 0.811765 0.929412 1"/>
      </material>
    </visual>
    <collision>
      <origin xyz="-0.00130076 -6.96521e-06 -0.0582746" rpy="-1.5708 -1.5708 0"/>
      <geometry>
        <mesh filename="package://assets/l_shoulder.stl"/>
      </geometry>
    </collision>
    <!-- Part rotor_x6_p20_60_2 -->
    <visual>
      <origin xyz="-0.0385 1.13164e-17 -0.078" rpy="-3.14159 -1.5708 0"/>
      <geometry>
        <mesh filename="package://assets/rotor_x6_p20_60.stl"/>
      </geometry>
      <material name="rotor_x6_p20_60_2_material">
        <color rgba="0.65098 0.486275 0.0196078 1"/>
      </material>
    </visual>
    <collision>
      <origin xyz="-0.0385 1.13164e-17 -0.078" rpy="-3.14159 -1.5708 0"/>
      <geometry>
        <mesh filename="package://assets/rotor_x6_p20_60.stl"/>
      </geometry>
    </collision>
    <!-- Part stator_x6_p20_60_2 -->
    <visual>
      <origin xyz="-0.0385 1.00153e-17 -0.078" rpy="-3.14159 -1.5708 0"/>
      <geometry>
        <mesh filename="package://assets/stator_x6_p20_60.stl"/>
      </geometry>
      <material name="stator_x6_p20_60_2_material">
        <color rgba="0.960784 0.835294 0.470588 1"/>
      </material>
    </visual>
    <collision>
      <origin xyz="-0.0385 1.00153e-17 -0.078" rpy="-3.14159 -1.5708 0"/>
      <geometry>
        <mesh filename="package://assets/stator_x6_p20_60.stl"/>
      </geometry>
    </collision>
  </link>
  <!-- Link urdf_l_upper_arm_assembly -->
  <link name="urdf_l_upper_arm_assembly">
    <inertial>
      <origin xyz="-0.112126 -2.19492e-08 0.0230405" rpy="0 0 0"/>
      <mass value="1.54329"/>
      <inertia ixx="0.00133766" ixy="6.04381e-10" ixz="0.000537695" iyy="0.00254134" iyz="7.1395e-08" izz="0.00234132"/>
    </inertial>
    <!-- Part l_upper_arm -->
    <visual>
      <origin xyz="-0.0912885 -6.25469e-08 0.00867029" rpy="-1.5708 2.039e-46 -1.5708"/>
      <geometry>
        <mesh filename="package://assets/l_upper_arm.stl"/>
      </geometry>
      <material name="l_upper_arm_material">
        <color rgba="0.615686 0.811765 0.929412 1"/>
      </material>
    </visual>
    <collision>
      <origin xyz="-0.0912885 -6.25469e-08 0.00867029" rpy="-1.5708 2.039e-46 -1.5708"/>
      <geometry>
        <mesh filename="package://assets/l_upper_arm.stl"/>
      </geometry>
    </collision>
    <!-- Part rotor_x4_p36_36 -->
    <visual>
      <origin xyz="-0.091 -2.77556e-17 0.029" rpy="1.5708 -2.13104e-30 -1.5708"/>
      <geometry>
        <mesh filename="package://assets/rotor_x4_p36_36.stl"/>
      </geometry>
      <material name="rotor_x4_p36_36_material">
        <color rgba="0.380392 0.0470588 0.435294 1"/>
      </material>
    </visual>
    <collision>
      <origin xyz="-0.091 -2.77556e-17 0.029" rpy="1.5708 -2.13104e-30 -1.5708"/>
      <geometry>
        <mesh filename="package://assets/rotor_x4_p36_36.stl"/>
      </geometry>
    </collision>
    <!-- Part stator_x4_p36_36 -->
    <visual>
      <origin xyz="-0.091 -3.46945e-17 0.029" rpy="1.5708 -4.10319e-30 -1.5708"/>
      <geometry>
        <mesh filename="package://assets/stator_x4_p36_36.stl"/>
      </geometry>
      <material name="stator_x4_p36_36_material">
        <color rgba="0.764706 0.545098 0.803922 1"/>
      </material>
    </visual>
    <collision>
      <origin xyz="-0.091 -3.46945e-17 0.029" rpy="1.5708 -4.10319e-30 -1.5708"/>
      <geometry>
        <mesh filename="package://assets/stator_x4_p36_36.stl"/>
      </geometry>
    </collision>
  </link>
  <!-- Link urdf_l_elbow_assembly -->
  <link name="urdf_l_elbow_assembly">
    <inertial>
      <origin xyz="0.0103789 1.30908e-06 -0.0814648" rpy="0 0 0"/>
      <mass value="2.87437"/>
      <inertia ixx="0.00300002" ixy="3.78723e-08" ixz="7.45868e-05" iyy="0.00280783" iyz="1.59723e-08" izz="0.00247115"/>
    </inertial>
    <!-- Part l_elbow -->
    <visual>
      <origin xyz="-0.000331628 1.15447e-05 -0.0692953" rpy="1.97215e-31 -0 1.30832e-20"/>
      <geometry>
        <mesh filename="package://assets/l_elbow.stl"/>
      </geometry>
      <material name="l_elbow_material">
        <color rgba="0.615686 0.811765 0.929412 1"/>
      </material>
    </visual>
    <collision>
      <origin xyz="-0.000331628 1.15447e-05 -0.0692953" rpy="1.97215e-31 -0 1.30832e-20"/>
      <geometry>
        <mesh filename="package://assets/l_elbow.stl"/>
      </geometry>
    </collision>
    <!-- Part rotor_x6_p20_60_3 -->
    <visual>
      <origin xyz="0.0445 4.77049e-18 -0.083" rpy="-3.14159 1.5708 0"/>
      <geometry>
        <mesh filename="package://assets/rotor_x6_p20_60.stl"/>
      </geometry>
      <material name="rotor_x6_p20_60_3_material">
        <color rgba="0.65098 0.486275 0.0196078 1"/>
      </material>
    </visual>
    <collision>
      <origin xyz="0.0445 4.77049e-18 -0.083" rpy="-3.14159 1.5708 0"/>
      <geometry>
        <mesh filename="package://assets/rotor_x6_p20_60.stl"/>
      </geometry>
    </collision>
    <!-- Part stator_x6_p20_60_3 -->
    <visual>
      <origin xyz="0.0445 1.30104e-18 -0.083" rpy="3.14159 1.5708 0"/>
      <geometry>
        <mesh filename="package://assets/stator_x6_p20_60.stl"/>
      </geometry>
      <material name="stator_x6_p20_60_3_material">
        <color rgba="0.960784 0.835294 0.470588 1"/>
      </material>
    </visual>
    <collision>
      <origin xyz="0.0445 1.30104e-18 -0.083" rpy="3.14159 1.5708 0"/>
      <geometry>
        <mesh filename="package://assets/stator_x6_p20_60.stl"/>
      </geometry>
    </collision>
  </link>
  <!-- Link urdf_l_upper_forearm_assembly -->
  <link name="urdf_l_upper_forearm_assembly">
    <inertial>
      <origin xyz="0.00126439 -0.111037 0.0195224" rpy="0 0 0"/>
      <mass value="1.44829"/>
      <inertia ixx="0.00214741" ixy="-9.87926e-07" ixz="-6.26246e-06" iyy="0.000998643" iyz="0.000395055" izz="0.00190798"/>
    </inertial>
    <!-- Part l_upper_forearm -->
    <visual>
      <origin xyz="0.0046701 -0.0842108 0.00848547" rpy="-1.5708 -1.5708 0"/>
      <geometry>
        <mesh filename="package://assets/l_upper_forearm.stl"/>
      </geometry>
      <material name="l_upper_forearm_material">
        <color rgba="0.615686 0.811765 0.929412 1"/>
      </material>
    </visual>
    <collision>
      <origin xyz="0.0046701 -0.0842108 0.00848547" rpy="-1.5708 -1.5708 0"/>
      <geometry>
        <mesh filename="package://assets/l_upper_forearm.stl"/>
      </geometry>
    </collision>
    <!-- Part rotor_x4_p36_36_2 -->
    <visual>
      <origin xyz="-6.50521e-19 -0.09 0.023" rpy="1.5708 -1.5708 0"/>
      <geometry>
        <mesh filename="package://assets/rotor_x4_p36_36.stl"/>
      </geometry>
      <material name="rotor_x4_p36_36_2_material">
        <color rgba="0.380392 0.0470588 0.435294 1"/>
      </material>
    </visual>
    <collision>
      <origin xyz="-6.50521e-19 -0.09 0.023" rpy="1.5708 -1.5708 0"/>
      <geometry>
        <mesh filename="package://assets/rotor_x4_p36_36.stl"/>
      </geometry>
    </collision>
    <!-- Part stator_x4_p36_36_2 -->
    <visual>
      <origin xyz="-6.50521e-19 -0.09 0.023" rpy="1.5708 -1.5708 0"/>
      <geometry>
        <mesh filename="package://assets/stator_x4_p36_36.stl"/>
      </geometry>
      <material name="stator_x4_p36_36_2_material">
        <color rgba="0.764706 0.545098 0.803922 1"/>
      </material>
    </visual>
    <collision>
      <origin xyz="-6.50521e-19 -0.09 0.023" rpy="1.5708 -1.5708 0"/>
      <geometry>
        <mesh filename="package://assets/stator_x4_p36_36.stl"/>
      </geometry>
    </collision>
  </link>
  <!-- Link urdf_l_lower_forearm_assembly -->
  <link name="urdf_l_lower_forearm_assembly">
    <inertial>
      <origin xyz="-2.78156e-05 0.00215422 -0.147028" rpy="0 0 0"/>
      <mass value="0.558"/>
      <inertia ixx="0.00382826" ixy="-3.16312e-08" ixz="2.02243e-07" iyy="0.00375463" iyz="-2.11667e-05" izz="0.000416359"/>
    </inertial>
    <!-- Part f3 -->
    <visual>
      <origin xyz="1.38778e-17 -8.67362e-19 -0.252" rpy="6.12396e-17 -1.98233e-16 1.5708"/>
      <geometry>
        <mesh filename="package://assets/f3.stl"/>
      </geometry>
      <material name="f3_material">
        <color rgba="1 1 1 1"/>
      </material>
    </visual>
    <collision>
      <origin xyz="1.38778e-17 -8.67362e-19 -0.252" rpy="6.12396e-17 -1.98233e-16 1.5708"/>
      <geometry>
        <mesh filename="package://assets/f3.stl"/>
      </geometry>
    </collision>
    <!-- Part f4 -->
    <visual>
      <origin xyz="1.38778e-17 -8.67362e-19 -0.252" rpy="6.12396e-17 -1.98233e-16 1.5708"/>
      <geometry>
        <mesh filename="package://assets/f4.stl"/>
      </geometry>
      <material name="f4_material">
        <color rgba="1 1 1 1"/>
      </material>
    </visual>
    <collision>
      <origin xyz="1.38778e-17 -8.67362e-19 -0.252" rpy="6.12396e-17 -1.98233e-16 1.5708"/>
      <geometry>
        <mesh filename="package://assets/f4.stl"/>
      </geometry>
    </collision>
    <!-- Part f1 -->
    <visual>
      <origin xyz="1.38778e-17 -8.67362e-19 -0.252" rpy="6.12396e-17 -1.98233e-16 1.5708"/>
      <geometry>
        <mesh filename="package://assets/f1.stl"/>
      </geometry>
      <material name="f1_material">
        <color rgba="1 1 1 1"/>
      </material>
    </visual>
    <collision>
      <origin xyz="1.38778e-17 -8.67362e-19 -0.252" rpy="6.12396e-17 -1.98233e-16 1.5708"/>
      <geometry>
        <mesh filename="package://assets/f1.stl"/>
      </geometry>
    </collision>
    <!-- Part hand -->
    <visual>
      <origin xyz="1.38778e-17 -8.67362e-19 -0.252" rpy="6.12396e-17 -1.98233e-16 1.5708"/>
      <geometry>
        <mesh filename="package://assets/hand.stl"/>
      </geometry>
      <material name="hand_material">
        <color rgba="1 1 1 1"/>
      </material>
    </visual>
    <collision>
      <origin xyz="1.38778e-17 -8.67362e-19 -0.252" rpy="6.12396e-17 -1.98233e-16 1.5708"/>
      <geometry>
        <mesh filename="package://assets/hand.stl"/>
      </geometry>
    </collision>
    <!-- Part f5 -->
    <visual>
      <origin xyz="1.38778e-17 -8.67362e-19 -0.252" rpy="6.12396e-17 -1.98233e-16 1.5708"/>
      <geometry>
        <mesh filename="package://assets/f5.stl"/>
      </geometry>
      <material name="f5_material">
        <color rgba="1 1 1 1"/>
      </material>
    </visual>
    <collision>
      <origin xyz="1.38778e-17 -8.67362e-19 -0.252" rpy="6.12396e-17 -1.98233e-16 1.5708"/>
      <geometry>
        <mesh filename="package://assets/f5.stl"/>
      </geometry>
    </collision>
    <!-- Part f2 -->
    <visual>
      <origin xyz="1.38778e-17 -8.67362e-19 -0.252" rpy="6.12396e-17 -1.98233e-16 1.5708"/>
      <geometry>
        <mesh filename="package://assets/f2.stl"/>
      </geometry>
      <material name="f2_material">
        <color rgba="1 1 1 1"/>
      </material>
    </visual>
    <collision>
      <origin xyz="1.38778e-17 -8.67362e-19 -0.252" rpy="6.12396e-17 -1.98233e-16 1.5708"/>
      <geometry>
        <mesh filename="package://assets/f2.stl"/>
      </geometry>
    </collision>
    <!-- Part l_lower_forearm -->
    <visual>
      <origin xyz="-6.05561e-05 0.00294052 -0.075703" rpy="-2.68917e-20 6.1232e-17 -1.01113e-14"/>
      <geometry>
        <mesh filename="package://assets/l_lower_forearm.stl"/>
      </geometry>
      <material name="l_lower_forearm_material">
        <color rgba="0.615686 0.811765 0.929412 1"/>
      </material>
    </visual>
    <collision>
      <origin xyz="-6.05561e-05 0.00294052 -0.075703" rpy="-2.68917e-20 6.1232e-17 -1.01113e-14"/>
      <geometry>
        <mesh filename="package://assets/l_lower_forearm.stl"/>
      </geometry>
    </collision>
  </link>
  <!-- Joint from urdf_l_upper_forearm_assembly to urdf_l_lower_forearm_assembly -->
  <joint name="elbow_yaw_joint" type="revolute">
    <origin xyz="7.37257e-17 -0.151 0.023" rpy="-1.5708 -1.5708 0"/>
    <parent link="urdf_l_upper_forearm_assembly"/>
    <child link="urdf_l_lower_forearm_assembly"/>
    <axis xyz="0 0 1"/>
    <limit effort="10" velocity="10" lower="-1.5708" upper="1.5708"/>
  </joint>
  <!-- Joint from urdf_l_elbow_assembly to urdf_l_upper_forearm_assembly -->
  <joint name="elbow_pitch_joint" type="revolute">
    <origin xyz="-0.023 4.35849e-17 -0.083" rpy="1.5708 -7.42674e-05 1.5708"/>
    <parent link="urdf_l_elbow_assembly"/>
    <child link="urdf_l_upper_forearm_assembly"/>
    <axis xyz="0 0 1"/>
    <limit effort="10" velocity="10" lower="-1.57087" upper="1.57072"/>
  </joint>
  <!-- Joint from urdf_l_upper_arm_assembly to urdf_l_elbow_assembly -->
  <joint name="shoulder_yaw_joint" type="revolute">
    <origin xyz="-0.157 -1.83881e-16 0.029" rpy="-1.5708 0.000395729 -1.5708"/>
    <parent link="urdf_l_upper_arm_assembly"/>
    <child link="urdf_l_elbow_assembly"/>
    <axis xyz="0 0 1"/>
    <limit effort="10" velocity="10" lower="-1.57119" upper="1.5704"/>
  </joint>
  <!-- Joint from urdf_l_shoulder_assembly to urdf_l_upper_arm_assembly -->
  <joint name="shoulder_roll_joint" type="revolute">
    <origin xyz="0.029 1.02101e-17 -0.078" rpy="-1.5708 -9.59268e-17 1.5708"/>
    <parent link="urdf_l_shoulder_assembly"/>
    <child link="urdf_l_upper_arm_assembly"/>
    <axis xyz="0 0 1"/>
    <limit effort="10" velocity="10" lower="-1.13446" upper="2.00713"/>
  </joint>
  <!-- Joint from urdf_l_limb_stand_assembly to urdf_l_shoulder_assembly -->
  <joint name="shoulder_pitch_joint" type="revolute">
    <origin xyz="0.0498579 0.00126819 6.80296e-06" rpy="1.5708 1.59595e-15 1.5708"/>
    <parent link="urdf_l_limb_stand_assembly"/>
    <child link="urdf_l_shoulder_assembly"/>
    <axis xyz="0 0 1"/>
    <limit effort="10" velocity="10" lower="-1.5708" upper="1.5708"/>
  </joint>
</robot>
