<?xml version="1.0"?>
<robot xmlns:xacro="http://www.ros.org/wiki/xacro" name="myactuator_arm">
  <xacro:arg name="pkg_share" default=""/>

  <!-- Base link (fixed to world) -->
  <link name="world"/>

  <!-- Joint 1 (EtherCAT slave position 0) -->
  <link name="link1">
    <visual>
      <geometry>
        <cylinder radius="0.05" length="0.1"/>
      </geometry>
      <origin xyz="0 0 0" rpy="0 0 0"/>
    </visual>
  </link>

  <joint name="joint1" type="revolute">
    <parent link="world"/>
    <child link="link1"/>
    <origin xyz="0 0.15 0" rpy="0 0 0"/>
    <axis xyz="0 0 1"/>
    <limit lower="-0.75" upper="3.14" velocity="16.0" effort="3.0"/>
  </joint>

  <!-- Joint 2 (EtherCAT slave position 1) -->
  <link name="link2">
    <visual>
      <geometry>
        <cylinder radius="0.05" length="0.1"/>
      </geometry>
      <origin xyz="0 0 0" rpy="0 0 0"/>
    </visual>
  </link>

  <joint name="joint2" type="revolute">
    <parent link="world"/>
    <child link="link2"/>
    <origin xyz="0 -0.15 0" rpy="0 0 0"/>
    <axis xyz="0 0 1"/>
    <limit lower="-2.98" upper="0.2" velocity="16.0" effort="3.0"/>
  </joint>

  <!-- ros2_control configuration - CST (Torque) mode for free movement -->
  <ros2_control name="EthercatSystem" type="system">
    <hardware>
      <plugin>ethercat_driver/EthercatDriver</plugin>
      <param name="master_id">0</param>
      <param name="control_frequency">250</param>
    </hardware>

    <!-- Joint 1 - EtherCAT slave position 0 -->
    <joint name="joint1">
      <command_interface name="velocity"/>
      <command_interface name="position"/>
      <command_interface name="effort"/>
      <state_interface name="position"/>
      <state_interface name="velocity"/>
      <state_interface name="effort"/>
      <ec_module name="MyActuatorX6_Joint1">
        <plugin>ethercat_generic_plugins/EcCiA402Drive</plugin>
        <param name="alias">0</param>
        <param name="position">0</param>
        <param name="slave_config">$(arg pkg_share)/config/ethercat/joint1_motor.yaml</param>
        <param name="mode_of_operation">10</param>
      </ec_module>
    </joint>

    <!-- Joint 2 - EtherCAT slave position 1 -->
    <joint name="joint2">
      <command_interface name="velocity"/>
      <command_interface name="position"/>
      <command_interface name="effort"/>
      <state_interface name="position"/>
      <state_interface name="velocity"/>
      <state_interface name="effort"/>
      <ec_module name="MyActuatorX6_Joint2">
        <plugin>ethercat_generic_plugins/EcCiA402Drive</plugin>
        <param name="alias">0</param>
        <param name="position">1</param>
        <param name="slave_config">$(arg pkg_share)/config/ethercat/joint2_motor.yaml</param>
        <param name="mode_of_operation">10</param>
      </ec_module>
    </joint>
  </ros2_control>

</robot>
